Workbook

Sheet 📊 Executive Dashboard
A2: LEGO SET VALUE POTENTIAL — PREDICTIVE ANALYTICS
A3: By Rahma Nazir 24i-5087
A4: Secondary Market Dataset · 2,322 LEGO Sets (1981–2014) · OLS Regression · R²=0.85 · MAE=$7.93 · Source: brickpicker.com
A7: SETS ANALYSED | D7: MODEL R² | G7: MEAN ABS ERROR | J7: MEDIAN ROI (NEW) | M7: CROSS-VAL R²
A8: ='📐 Model Performance'!B11 -> 2322 | D8: ='📐 Model Performance'!B5 -> 0.8477 | G8: ='📐 Model Performance'!B7 -> 7.99 | J8: =MEDIAN('📋 Data & Predictions'!$N$4:$N$77) -> 84.035652 | M8: ='📐 Model Performance'!B5 -> 0.8477
A9: 1981–2014 releases | D9: 85% variance explained | G9: Avg prediction accuracy | J9: Vs original retail price | M9: 5-Fold CV mean score
A12: 📈 SECONDARY MARKET ROI — TOP 10 THEMES (NEW SETS) | G12: 🔍 PRICE DRIVERS — CORRELATION | K12: ✅ MODEL PERFORMANCE — CROSS VALIDATION (5-FOLD)
A13: Theme | B13: Retail ($) | C13: Sec.Mkt ($) | D13: ROI (%) | E13: Rank | G13: Variable | H13: Corr. (r) | I13: Strength | J13: Direction | K13: Fold | L13: R² Score | M13: Rating | N13: Status | O13: Notes
A14: Super Heroes | B14: =VLOOKUP("Super Heroes",'🎯 Theme Analysis'!$A:$I,3,FALSE()) -> 31.3 | C14: =VLOOKUP("Super Heroes",'🎯 Theme Analysis'!$A:$I,7,FALSE()) -> 180 | D14: =VLOOKUP("Super Heroes",'🎯 Theme Analysis'!$A:$I,8,FALSE()) -> 475.07987 | E14: =RANK(D14,$D$14:$D$23,0) -> 2 | G14: # of Pieces | H14: ='📐 Model Performance'!B28 -> 0.921 | I14: Very Strong | J14: ↑ Positive | K14: Fold 1 | L14: ='📐 Model Performance'!B12 -> 0.9039 | M14: =IF(L14>=0.9,"Excellent",IF(L14>=0.8,"Strong","Moderate")) -> Excellent | N14: =IF(L14>=0.8,"✓ STRONG","⚠ MODERATE") -> ✓ STRONG | O14: Best performing fold
A15: Castle | B15: =VLOOKUP("Castle",'🎯 Theme Analysis'!$A:$I,3,FALSE()) -> 68.49 | C15: =VLOOKUP("Castle",'🎯 Theme Analysis'!$A:$I,7,FALSE()) -> 253.305 | D15: =VLOOKUP("Castle",'🎯 Theme Analysis'!$A:$I,8,FALSE()) -> 269.84231 | E15: =RANK(D15,$D$14:$D$23,0) -> 4 | G15: Size Group | H15: ='📐 Model Performance'!B29 -> 0.848 | I15: Very Strong | J15: ↑ Positive | K15: Fold 2 | L15: ='📐 Model Performance'!B13 -> 0.6481 | M15: =IF(L15>=0.9,"Excellent",IF(L15>=0.8,"Strong","Moderate")) -> Moderate | N15: =IF(L15>=0.8,"✓ STRONG","⚠ MODERATE") -> ⚠ MODERATE | O15: Heterogeneous subset
A16: Advanced Models | B16: =VLOOKUP("Advanced Models",'🎯 Theme Analysis'!$A:$I,3,FALSE()) -> 213.615 | C16: =VLOOKUP("Advanced Models",'🎯 Theme Analysis'!$A:$I,7,FALSE()) -> 1472.9362 | D16: =VLOOKUP("Advanced Models",'🎯 Theme Analysis'!$A:$I,8,FALSE()) -> 589.52847 | E16: =RANK(D16,$D$14:$D$23,0) -> 1 | G16: Minifigures | H16: ='📐 Model Performance'!B30 -> 0.418 | I16: Moderate | J16: ↑ Positive | K16: Fold 3 | L16: ='📐 Model Performance'!B14 -> 0.8961 | M16: =IF(L16>=0.9,"Excellent",IF(L16>=0.8,"Strong","Moderate")) -> Strong | N16: =IF(L16>=0.8,"✓ STRONG","⚠ MODERATE") -> ✓ STRONG | O16: Consistent performance
A17: Harry Potter | B17: =VLOOKUP("Harry Potter",'🎯 Theme Analysis'!$A:$I,3,FALSE()) -> 133.32333 | C17: =VLOOKUP("Harry Potter",'🎯 Theme Analysis'!$A:$I,7,FALSE()) -> 375.83333 | D17: =VLOOKUP("Harry Potter",'🎯 Theme Analysis'!$A:$I,8,FALSE()) -> 181.89614 | E17: =RANK(D17,$D$14:$D$23,0) -> 6 | G17: Year Release | H17: ='📐 Model Performance'!B31 -> 0.073 | I17: Very Weak | J17: ↑ Positive | K17: Fold 4 | L17: ='📐 Model Performance'!B15 -> 0.8755 | M17: =IF(L17>=0.9,"Excellent",IF(L17>=0.8,"Strong","Moderate")) -> Strong | N17: =IF(L17>=0.8,"✓ STRONG","⚠ MODERATE") -> ✓ STRONG | O17: Consistent performance
A18: Pirates | B18: =VLOOKUP("Pirates",'🎯 Theme Analysis'!$A:$I,3,FALSE()) -> 138.99 | C18: =VLOOKUP("Pirates",'🎯 Theme Analysis'!$A:$I,7,FALSE()) -> 534.63333 | D18: =VLOOKUP("Pirates",'🎯 Theme Analysis'!$A:$I,8,FALSE()) -> 284.65597 | E18: =RANK(D18,$D$14:$D$23,0) -> 3 | K18: Fold 5 | L18: ='📐 Model Performance'!B16 -> 0.9149 | M18: =IF(L18>=0.9,"Excellent",IF(L18>=0.8,"Strong","Moderate")) -> Excellent | N18: =IF(L18>=0.8,"✓ STRONG","⚠ MODERATE") -> ✓ STRONG | O18: Best performing fold
A19: Batman | B19: =VLOOKUP("Batman",'🎯 Theme Analysis'!$A:$I,3,FALSE()) -> 89.99 | C19: =VLOOKUP("Batman",'🎯 Theme Analysis'!$A:$I,7,FALSE()) -> 223.332 | D19: =VLOOKUP("Batman",'🎯 Theme Analysis'!$A:$I,8,FALSE()) -> 148.17424 | E19: =RANK(D19,$D$14:$D$23,0) -> 7 | G19: 📐 REGRESSION COEFFICIENTS | K19: MEAN | L19: ='📐 Model Performance'!B5 -> 0.8477 | M19: =IF(L19>=0.9,"Excellent",IF(L19>=0.8,"Strong","Moderate")) -> Strong | N19: =IF(L19>=0.8,"✓ STRONG","⚠ MODERATE") -> ✓ STRONG | O19: Overall model quality
A20: Bionicle | B20: =VLOOKUP("Bionicle",'🎯 Theme Analysis'!$A:$I,3,FALSE()) -> 26.656667 | C20: =VLOOKUP("Bionicle",'🎯 Theme Analysis'!$A:$I,7,FALSE()) -> 92.916667 | D20: =VLOOKUP("Bionicle",'🎯 Theme Analysis'!$A:$I,8,FALSE()) -> 248.56821 | E20: =RANK(D20,$D$14:$D$23,0) -> 5 | G20: Parameter | H20: Coefficient | I20: Unit | J20: Interpretation | K20: 📦 RETAIL PRICE BY SET SIZE
A21: Monster Fighters | B21: =VLOOKUP("Monster Fighters",'🎯 Theme Analysis'!$A:$I,3,FALSE()) -> 179.99 | C21: =VLOOKUP("Monster Fighters",'🎯 Theme Analysis'!$A:$I,7,FALSE()) -> 304.13 | D21: =VLOOKUP("Monster Fighters",'🎯 Theme Analysis'!$A:$I,8,FALSE()) -> 68.970498 | E21: =RANK(D21,$D$14:$D$23,0) -> 8 | G21: β0 – Intercept | H21: ='🧮 Price Calculator'!$B$30 -> 35.3652 | I21: USD | J21: Base price before features | K21: Size Group | L21: Desc. | M21: Sets (n) | N21: Avg Price | O21: % of Total
A22: Star Wars | B22: =VLOOKUP("Star Wars",'🎯 Theme Analysis'!$A:$I,3,FALSE()) -> 257.40667 | C22: =VLOOKUP("Star Wars",'🎯 Theme Analysis'!$A:$I,7,FALSE()) -> 407.93083 | D22: =VLOOKUP("Star Wars",'🎯 Theme Analysis'!$A:$I,8,FALSE()) -> 58.477183 | E22: =RANK(D22,$D$14:$D$23,0) -> 9 | G22: β1 – Pieces | H22: ='🧮 Price Calculator'!$B$31 -> 0.0695 | I22: $/piece | J22: +$0.07 per additional piece | K22: Group 1 | L22: Largest (800+pcs) | M22: ='📈 Charts & Analysis'!H63 -> 55 | N22: ='📈 Charts & Analysis'!K63 -> 184.262 | O22: =M22/SUM($M$22:$M$25) -> 0.74324324
A23: City | B23: =VLOOKUP("City",'🎯 Theme Analysis'!$A:$I,3,FALSE()) -> 134.99 | C23: =VLOOKUP("City",'🎯 Theme Analysis'!$A:$I,7,FALSE()) -> 157.112 | D23: =VLOOKUP("City",'🎯 Theme Analysis'!$A:$I,8,FALSE()) -> 16.387881 | E23: =RANK(D23,$D$14:$D$23,0) -> 10 | G23: β2 – Minifigs | H23: ='🧮 Price Calculator'!$B$32 -> 1.6686 | I23: $/fig | J23: +$1.67 per minifigure | K23: Group 2 | L23: Large (300-800pcs) | M23: ='📈 Charts & Analysis'!H64 -> 8 | N23: ='📈 Charts & Analysis'!K64 -> 90.185 | O23: =M23/SUM($M$22:$M$25) -> 0.10810811
G24: β3 – Size Group | H24: ='🧮 Price Calculator'!$B$33 -> -8.1964 | I24: $/group | J24: Larger set = higher price | K24: Group 3 | L24: Medium (100-300pcs) | M24: ='📈 Charts & Analysis'!H65 -> 9 | N24: ='📈 Charts & Analysis'!K65 -> 28.33 | O24: =M24/SUM($M$22:$M$25) -> 0.12162162
G25: β4 – Theme | H25: ='🧮 Price Calculator'!$B$34 -> 0.1164 | I25: $/unit | J25: Marginal theme premium | K25: Group 4 | L25: Small (<100pcs) | M25: ='📈 Charts & Analysis'!H66 -> 2 | N25: ='📈 Charts & Analysis'!K66 -> 24.99 | O25: =M25/SUM($M$22:$M$25) -> 0.027027027
A29: 📌 PREDICTION FORMULA: Price = 35.3652 + (0.0695 × Pieces) + (1.6686 × Minifigs) + (–8.1964 × SizeGroup) + (0.1164 × ThemeID)
A30: Source: Maciorowski & Maciorowski (2015) via brickpicker.com / eBay · Model: OLS Linear Regression · Dataset: 2,322 sets (1981–2014) · All prices in USD

Sheet 📈 Charts & Analysis
A1: LEGO PREDICTIVE ANALYTICS — VISUAL ANALYSIS & CHARTS
A3: 📊 Secondary Market ROI (%) by Theme — Top 12 Themes | K3: 💰 Average Retail Price ($) by Theme — Top 10 Themes
A22: 🥧 Set Size Distribution — % of Total Dataset (2,322 Sets) | K22: 📦 Average Retail Price ($) by Set Size Group
A40: 📉 Model R² Score — 5-Fold Cross Validation Results | K40: 🔍 Price Predictor Correlation Strength |r|
A62: Theme | B62: ROI New (%) | D62: Theme | E62: Avg Retail ($) | G62: Size Group | H62: Count | J62: Size Group | K62: Avg Price ($) | M62: Fold | N62: R² Score | O62: Mean R² | Q62: Predictor | R62: |r|
A63: Super Heroes | B63: =VLOOKUP("Super Heroes",'🎯 Theme Analysis'!$A:$I,8,FALSE()) -> 475.07987 | D63: Adv. Models | E63: =VLOOKUP("Advanced Models",'🎯 Theme Analysis'!$A:$I,3,FALSE()) -> 213.615 | G63: Largest (800+) | H63: =COUNTIF('📋 Data & Predictions'!$G$4:$G$77,1) -> 55 | J63: Largest | K63: =AVERAGEIF('📋 Data & Predictions'!$G$4:$G$77,1,'📋 Data & Predictions'!$H$4:$H$77) -> 184.262 | M63: Fold 1 | N63: ='📐 Model Performance'!B12 -> 0.9039 | O63: ='📐 Model Performance'!B5 -> 0.8477 | Q63: Pieces | R63: ='📐 Model Performance'!B28 -> 0.921
A64: Castle | B64: =VLOOKUP("Castle",'🎯 Theme Analysis'!$A:$I,8,FALSE()) -> 269.84231 | D64: Architecture | E64: =VLOOKUP("Architecture",'🎯 Theme Analysis'!$A:$I,3,FALSE()) -> 174.99 | G64: Large (300-800) | H64: =COUNTIF('📋 Data & Predictions'!$G$4:$G$77,2) -> 8 | J64: Large | K64: =AVERAGEIF('📋 Data & Predictions'!$G$4:$G$77,2,'📋 Data & Predictions'!$H$4:$H$77) -> 90.185 | M64: Fold 2 | N64: ='📐 Model Performance'!B13 -> 0.6481 | O64: ='📐 Model Performance'!B5 -> 0.8477 | Q64: Size Group | R64: ='📐 Model Performance'!B29 -> 0.848
A65: Adv. Models | B65: =VLOOKUP("Advanced Models",'🎯 Theme Analysis'!$A:$I,8,FALSE()) -> 589.52847 | D65: Technic | E65: =VLOOKUP("Technic",'🎯 Theme Analysis'!$A:$I,3,FALSE()) -> 191.65 | G65: Medium (100-300) | H65: =COUNTIF('📋 Data & Predictions'!$G$4:$G$77,3) -> 9 | J65: Medium | K65: =AVERAGEIF('📋 Data & Predictions'!$G$4:$G$77,3,'📋 Data & Predictions'!$H$4:$H$77) -> 28.33 | M65: Fold 3 | N65: ='📐 Model Performance'!B14 -> 0.8961 | O65: ='📐 Model Performance'!B5 -> 0.8477 | Q65: Minifigs | R65: ='📐 Model Performance'!B30 -> 0.418
A66: Harry Potter | B66: =VLOOKUP("Harry Potter",'🎯 Theme Analysis'!$A:$I,8,FALSE()) -> 181.89614 | D66: LotR | E66: =VLOOKUP("Lord of the Rings",'🎯 Theme Analysis'!$A:$I,3,FALSE()) -> 153.32333 | G66: Small (<100) | H66: =COUNTIF('📋 Data & Predictions'!$G$4:$G$77,4) -> 2 | J66: Small | K66: =AVERAGEIF('📋 Data & Predictions'!$G$4:$G$77,4,'📋 Data & Predictions'!$H$4:$H$77) -> 24.99 | M66: Fold 4 | N66: ='📐 Model Performance'!B15 -> 0.8755 | O66: ='📐 Model Performance'!B5 -> 0.8477 | Q66: Year | R66: ='📐 Model Performance'!B31 -> 0.073
A67: Pirates | B67: =VLOOKUP("Pirates",'🎯 Theme Analysis'!$A:$I,8,FALSE()) -> 284.65597 | D67: Star Wars | E67: =VLOOKUP("Star Wars",'🎯 Theme Analysis'!$A:$I,3,FALSE()) -> 257.40667 | M67: Fold 5 | N67: ='📐 Model Performance'!B16 -> 0.9149 | O67: ='📐 Model Performance'!B5 -> 0.8477
A68: Batman | B68: =VLOOKUP("Batman",'🎯 Theme Analysis'!$A:$I,8,FALSE()) -> 148.17424 | D68: Minecraft | E68: =VLOOKUP("Minecraft",'🎯 Theme Analysis'!$A:$I,3,FALSE()) -> 109.99
A69: Indiana Jones | B69: =VLOOKUP("Indiana Jones",'🎯 Theme Analysis'!$A:$I,8,FALSE()) -> 201.25851 | D69: Batman | E69: =VLOOKUP("Batman",'🎯 Theme Analysis'!$A:$I,3,FALSE()) -> 89.99
A70: Monster Fighters | B70: =VLOOKUP("Monster Fighters",'🎯 Theme Analysis'!$A:$I,8,FALSE()) -> 68.970498 | D70: Harry Potter | E70: =VLOOKUP("Harry Potter",'🎯 Theme Analysis'!$A:$I,3,FALSE()) -> 133.32333
A71: Star Wars | B71: =VLOOKUP("Star Wars",'🎯 Theme Analysis'!$A:$I,8,FALSE()) -> 58.477183 | D71: City | E71: =VLOOKUP("City",'🎯 Theme Analysis'!$A:$I,3,FALSE()) -> 134.99
A72: Bionicle | B72: =VLOOKUP("Bionicle",'🎯 Theme Analysis'!$A:$I,8,FALSE()) -> 248.56821 | D72: Pirates | E72: =VLOOKUP("Pirates",'🎯 Theme Analysis'!$A:$I,3,FALSE()) -> 138.99
A73: City | B73: =VLOOKUP("City",'🎯 Theme Analysis'!$A:$I,8,FALSE()) -> 16.387881
A74: Technic | B74: =VLOOKUP("Technic",'🎯 Theme Analysis'!$A:$I,8,FALSE()) -> 69.910427

Sheet 🎯 Theme Analysis
A1: THEME-LEVEL ANALYSIS — Pricing Power & Secondary Market Returns
A2: Filter using column headers ▼ | Green = High ROI (300%+) | Orange = Strong ROI (200-300%) | Use Ctrl+F to search themes
A3: Theme | B3: Sets (n) | C3: Avg Retail ($) | D3: Avg Pieces | E3: Avg Minifigs | F3: Price/Piece ($) | G3: Avg Sec Mkt ($) | H3: ROI New (%) | I3: Power Score | J3: Category
A4: The Simpsons | B4: =COUNTIF('📋 Data & Predictions'!$B$4:$B$77,A4) -> 0 | C4: =IFERROR(IF(AVERAGEIF('📋 Data & Predictions'!$B$4:$B$77,A4,'📋 Data & Predictions'!$H$4:$H$77)=0,199.99,AVERAGEIF('📋 Data & Predictions'!$B$4:$B$77,A4,'📋 Data & Predictions'!$H$4:$H$77)),199.99) -> 199.99 | D4: =IFERROR(IF(AVERAGEIF('📋 Data & Predictions'!$B$4:$B$77,A4,'📋 Data & Predictions'!$E$4:$E$77)=0,2523,AVERAGEIF('📋 Data & Predictions'!$B$4:$B$77,A4,'📋 Data & Predictions'!$E$4:$E$77)),2523) -> 2523 | E4: =IFERROR(IF(AVERAGEIF('📋 Data & Predictions'!$B$4:$B$77,A4,'📋 Data & Predictions'!$F$4:$F$77)=0,6,AVERAGEIF('📋 Data & Predictions'!$B$4:$B$77,A4,'📋 Data & Predictions'!$F$4:$F$77)),6) -> 6 | F4: =IFERROR(C4/D4,0) -> 0.079266746 | G4: =IFERROR(IF(AVERAGEIF('📋 Data & Predictions'!$B$4:$B$77,A4,'📋 Data & Predictions'!$I$4:$I$77)=0,192.96,AVERAGEIF('📋 Data & Predictions'!$B$4:$B$77,A4,'📋 Data & Predictions'!$I$4:$I$77)),192.96) -> 192.96 | H4: =IFERROR((G4-C4)/C4*100,0) -> -3.5151758 | I4: =IFERROR(ROUND((H4/10)*0.5+(C4/200)*0.3+(E4/10)*0.2,1),49.6) -> 0.2 | J4: Premium/Niche
A5: Model Team | B5: =COUNTIF('📋 Data & Predictions'!$B$4:$B$77,A5) -> 0 | C5: =IFERROR(IF(AVERAGEIF('📋 Data & Predictions'!$B$4:$B$77,A5,'📋 Data & Predictions'!$H$4:$H$77)=0,138.99,AVERAGEIF('📋 Data & Predictions'!$B$4:$B$77,A5,'📋 Data & Predictions'!$H$4:$H$77)),138.99) -> 138.99 | D5: =IFERROR(IF(AVERAGEIF('📋 Data & Predictions'!$B$4:$B$77,A5,'📋 Data & Predictions'!$E$4:$E$77)=0,1757,AVERAGEIF('📋 Data & Predictions'!$B$4:$B$77,A5,'📋 Data & Predictions'!$E$4:$E$77)),1757) -> 1757 | E5: =IFERROR(IF(AVERAGEIF('📋 Data & Predictions'!$B$4:$B$77,A5,'📋 Data & Predictions'!$F$4:$F$77)=0,0,AVERAGEIF('📋 Data & Predictions'!$B$4:$B$77,A5,'📋 Data & Predictions'!$F$4:$F$77)),0) -> 0 | F5: =IFERROR(C5/D5,0) -> 0.079106431 | G5: =IFERROR(IF(AVERAGEIF('📋 Data & Predictions'!$B$4:$B$77,A5,'📋 Data & Predictions'!$I$4:$I$77)=0,655.73,AVERAGEIF('📋 Data & Predictions'!$B$4:$B$77,A5,'📋 Data & Predictions'!$I$4:$I$77)),655.73) -> 655.73 | H5: =IFERROR((G5-C5)/C5*100,0) -> 371.78214 | I5: =IFERROR(ROUND((H5/10)*0.5+(C5/200)*0.3+(E5/10)*0.2,1),72.1) -> 18.8 | J5: Premium/High ROI
A6: Advanced Models | B6: =COUNTIF('📋 Data & Predictions'!$B$4:$B$77,A6) -> 8 | C6: =IFERROR(IF(AVERAGEIF('📋 Data & Predictions'!$B$4:$B$77,A6,'📋 Data & Predictions'!$H$4:$H$77)=0,138.73,AVERAGEIF('📋 Data & Predictions'!$B$4:$B$77,A6,'📋 Data & Predictions'!$H$4:$H$77)),138.73) -> 213.615 | D6: =IFERROR(IF(AVERAGEIF('📋 Data & Predictions'!$B$4:$B$77,A6,'📋 Data & Predictions'!$E$4:$E$77)=0,1909,AVERAGEIF('📋 Data & Predictions'!$B$4:$B$77,A6,'📋 Data & Predictions'!$E$4:$E$77)),1909) -> 3109.125 | E6: =IFERROR(IF(AVERAGEIF('📋 Data & Predictions'!$B$4:$B$77,A6,'📋 Data & Predictions'!$F$4:$F$77)=0,2.3,AVERAGEIF('📋 Data & Predictions'!$B$4:$B$77,A6,'📋 Data & Predictions'!$F$4:$F$77)),2.3) -> 3 | F6: =IFERROR(C6/D6,0) -> 0.068705826 | G6: =IFERROR(IF(AVERAGEIF('📋 Data & Predictions'!$B$4:$B$77,A6,'📋 Data & Predictions'!$I$4:$I$77)=0,581.96,AVERAGEIF('📋 Data & Predictions'!$B$4:$B$77,A6,'📋 Data & Predictions'!$I$4:$I$77)),581.96) -> 1472.9362 | H6: =IFERROR((G6-C6)/C6*100,0) -> 589.52847 | I6: =IFERROR(ROUND((H6/10)*0.5+(C6/200)*0.3+(E6/10)*0.2,1),66.1) -> 29.9 | J6: Premium/High ROI
A7: Factory | B7: =COUNTIF('📋 Data & Predictions'!$B$4:$B$77,A7) -> 0 | C7: =IFERROR(IF(AVERAGEIF('📋 Data & Predictions'!$B$4:$B$77,A7,'📋 Data & Predictions'!$H$4:$H$77)=0,87.13,AVERAGEIF('📋 Data & Predictions'!$B$4:$B$77,A7,'📋 Data & Predictions'!$H$4:$H$77)),87.13) -> 87.13 | D7: =IFERROR(IF(AVERAGEIF('📋 Data & Predictions'!$B$4:$B$77,A7,'📋 Data & Predictions'!$E$4:$E$77)=0,1217,AVERAGEIF('📋 Data & Predictions'!$B$4:$B$77,A7,'📋 Data & Predictions'!$E$4:$E$77)),1217) -> 1217 | E7: =IFERROR(IF(AVERAGEIF('📋 Data & Predictions'!$B$4:$B$77,A7,'📋 Data & Predictions'!$F$4:$F$77)=0,2.3,AVERAGEIF('📋 Data & Predictions'!$B$4:$B$77,A7,'📋 Data & Predictions'!$F$4:$F$77)),2.3) -> 2.3 | F7: =IFERROR(C7/D7,0) -> 0.071594084 | G7: =IFERROR(IF(AVERAGEIF('📋 Data & Predictions'!$B$4:$B$77,A7,'📋 Data & Predictions'!$I$4:$I$77)=0,149.34,AVERAGEIF('📋 Data & Predictions'!$B$4:$B$77,A7,'📋 Data & Predictions'!$I$4:$I$77)),149.34) -> 149.34 | H7: =IFERROR((G7-C7)/C7*100,0) -> 71.399059 | I7: =IFERROR(ROUND((H7/10)*0.5+(C7/200)*0.3+(E7/10)*0.2,1),27.3) -> 3.7 | J7: High-End
A8: Racers | B8: =COUNTIF('📋 Data & Predictions'!$B$4:$B$77,A8) -> 1 | C8: =IFERROR(IF(AVERAGEIF('📋 Data & Predictions'!$B$4:$B$77,A8,'📋 Data & Predictions'!$H$4:$H$77)=0,63.61,AVERAGEIF('📋 Data & Predictions'!$B$4:$B$77,A8,'📋 Data & Predictions'!$H$4:$H$77)),63.61) -> 139.99 | D8: =IFERROR(IF(AVERAGEIF('📋 Data & Predictions'!$B$4:$B$77,A8,'📋 Data & Predictions'!$E$4:$E$77)=0,691,AVERAGEIF('📋 Data & Predictions'!$B$4:$B$77,A8,'📋 Data & Predictions'!$E$4:$E$77)),691) -> 1246 | E8: =IFERROR(IF(AVERAGEIF('📋 Data & Predictions'!$B$4:$B$77,A8,'📋 Data & Predictions'!$F$4:$F$77)=0,0.2,AVERAGEIF('📋 Data & Predictions'!$B$4:$B$77,A8,'📋 Data & Predictions'!$F$4:$F$77)),0.2) -> 0.2 | F8: =IFERROR(C8/D8,0) -> 0.11235152 | G8: =IFERROR(IF(AVERAGEIF('📋 Data & Predictions'!$B$4:$B$77,A8,'📋 Data & Predictions'!$I$4:$I$77)=0,213.35,AVERAGEIF('📋 Data & Predictions'!$B$4:$B$77,A8,'📋 Data & Predictions'!$I$4:$I$77)),213.35) -> 527.27 | H8: =IFERROR((G8-C8)/C8*100,0) -> 276.64833 | I8: =IFERROR(ROUND((H8/10)*0.5+(C8/200)*0.3+(E8/10)*0.2,1),31.9) -> 14 | J8: Mid-Tier
A9: Architecture | B9: =COUNTIF('📋 Data & Predictions'!$B$4:$B$77,A9) -> 2 | C9: =IFERROR(IF(AVERAGEIF('📋 Data & Predictions'!$B$4:$B$77,A9,'📋 Data & Predictions'!$H$4:$H$77)=0,58.99,AVERAGEIF('📋 Data & Predictions'!$B$4:$B$77,A9,'📋 Data & Predictions'!$H$4:$H$77)),58.99) -> 174.99 | D9: =IFERROR(IF(AVERAGEIF('📋 Data & Predictions'!$B$4:$B$77,A9,'📋 Data & Predictions'!$E$4:$E$77)=0,496,AVERAGEIF('📋 Data & Predictions'!$B$4:$B$77,A9,'📋 Data & Predictions'!$E$4:$E$77)),496) -> 1743.5 | E9: =IFERROR(IF(AVERAGEIF('📋 Data & Predictions'!$B$4:$B$77,A9,'📋 Data & Predictions'!$F$4:$F$77)=0,0,AVERAGEIF('📋 Data & Predictions'!$B$4:$B$77,A9,'📋 Data & Predictions'!$F$4:$F$77)),0) -> 0 | F9: =IFERROR(C9/D9,0) -> 0.10036708 | G9: =IFERROR(IF(AVERAGEIF('📋 Data & Predictions'!$B$4:$B$77,A9,'📋 Data & Predictions'!$I$4:$I$77)=0,94.66,AVERAGEIF('📋 Data & Predictions'!$B$4:$B$77,A9,'📋 Data & Predictions'!$I$4:$I$77)),94.66) -> 235.465 | H9: =IFERROR((G9-C9)/C9*100,0) -> 34.559118 | I9: =IFERROR(ROUND((H9/10)*0.5+(C9/200)*0.3+(E9/10)*0.2,1),24.3) -> 2 | J9: Mid-Tier
A10: Technic | B10: =COUNTIF('📋 Data & Predictions'!$B$4:$B$77,A10) -> 6 | C10: =IFERROR(IF(AVERAGEIF('📋 Data & Predictions'!$B$4:$B$77,A10,'📋 Data & Predictions'!$H$4:$H$77)=0,57.71,AVERAGEIF('📋 Data & Predictions'!$B$4:$B$77,A10,'📋 Data & Predictions'!$H$4:$H$77)),57.71) -> 191.65 | D10: =IFERROR(IF(AVERAGEIF('📋 Data & Predictions'!$B$4:$B$77,A10,'📋 Data & Predictions'!$E$4:$E$77)=0,579,AVERAGEIF('📋 Data & Predictions'!$B$4:$B$77,A10,'📋 Data & Predictions'!$E$4:$E$77)),579) -> 1536.1667 | E10: =IFERROR(IF(AVERAGEIF('📋 Data & Predictions'!$B$4:$B$77,A10,'📋 Data & Predictions'!$F$4:$F$77)=0,0,AVERAGEIF('📋 Data & Predictions'!$B$4:$B$77,A10,'📋 Data & Predictions'!$F$4:$F$77)),0) -> 0 | F10: =IFERROR(C10/D10,0) -> 0.1247586 | G10: =IFERROR(IF(AVERAGEIF('📋 Data & Predictions'!$B$4:$B$77,A10,'📋 Data & Predictions'!$I$4:$I$77)=0,115.62,AVERAGEIF('📋 Data & Predictions'!$B$4:$B$77,A10,'📋 Data & Predictions'!$I$4:$I$77)),115.62) -> 325.63333 | H10: =IFERROR((G10-C10)/C10*100,0) -> 69.910427 | I10: =IFERROR(ROUND((H10/10)*0.5+(C10/200)*0.3+(E10/10)*0.2,1),25) -> 3.8 | J10: Mid-Tier
A11: Trains | B11: =COUNTIF('📋 Data & Predictions'!$B$4:$B$77,A11) -> 5 | C11: =IFERROR(IF(AVERAGEIF('📋 Data & Predictions'!$B$4:$B$77,A11,'📋 Data & Predictions'!$H$4:$H$77)=0,50.2,AVERAGEIF('📋 Data & Predictions'!$B$4:$B$77,A11,'📋 Data & Predictions'!$H$4:$H$77)),50.2) -> 116.99 | D11: =IFERROR(IF(AVERAGEIF('📋 Data & Predictions'!$B$4:$B$77,A11,'📋 Data & Predictions'!$E$4:$E$77)=0,376,AVERAGEIF('📋 Data & Predictions'!$B$4:$B$77,A11,'📋 Data & Predictions'!$E$4:$E$77)),376) -> 731.4 | E11: =IFERROR(IF(AVERAGEIF('📋 Data & Predictions'!$B$4:$B$77,A11,'📋 Data & Predictions'!$F$4:$F$77)=0,1.8,AVERAGEIF('📋 Data & Predictions'!$B$4:$B$77,A11,'📋 Data & Predictions'!$F$4:$F$77)),1.8) -> 3.8 | F11: =IFERROR(C11/D11,0) -> 0.15995351 | G11: =IFERROR(IF(AVERAGEIF('📋 Data & Predictions'!$B$4:$B$77,A11,'📋 Data & Predictions'!$I$4:$I$77)=0,178.03,AVERAGEIF('📋 Data & Predictions'!$B$4:$B$77,A11,'📋 Data & Predictions'!$I$4:$I$77)),178.03) -> 241.264 | H11: =IFERROR((G11-C11)/C11*100,0) -> 106.22617 | I11: =IFERROR(ROUND((H11/10)*0.5+(C11/200)*0.3+(E11/10)*0.2,1),42.5) -> 5.6 | J11: High ROI
A12: Lord of the Rings | B12: =COUNTIF('📋 Data & Predictions'!$B$4:$B$77,A12) -> 3 | C12: =IFERROR(IF(AVERAGEIF('📋 Data & Predictions'!$B$4:$B$77,A12,'📋 Data & Predictions'!$H$4:$H$77)=0,48.24,AVERAGEIF('📋 Data & Predictions'!$B$4:$B$77,A12,'📋 Data & Predictions'!$H$4:$H$77)),48.24) -> 153.32333 | D12: =IFERROR(IF(AVERAGEIF('📋 Data & Predictions'!$B$4:$B$77,A12,'📋 Data & Predictions'!$E$4:$E$77)=0,439,AVERAGEIF('📋 Data & Predictions'!$B$4:$B$77,A12,'📋 Data & Predictions'!$E$4:$E$77)),439) -> 1531 | E12: =IFERROR(IF(AVERAGEIF('📋 Data & Predictions'!$B$4:$B$77,A12,'📋 Data & Predictions'!$F$4:$F$77)=0,4.3,AVERAGEIF('📋 Data & Predictions'!$B$4:$B$77,A12,'📋 Data & Predictions'!$F$4:$F$77)),4.3) -> 6 | F12: =IFERROR(C12/D12,0) -> 0.10014587 | G12: =IFERROR(IF(AVERAGEIF('📋 Data & Predictions'!$B$4:$B$77,A12,'📋 Data & Predictions'!$I$4:$I$77)=0,52.77,AVERAGEIF('📋 Data & Predictions'!$B$4:$B$77,A12,'📋 Data & Predictions'!$I$4:$I$77)),52.77) -> 177.65333 | H12: =IFERROR((G12-C12)/C12*100,0) -> 15.868426 | I12: =IFERROR(ROUND((H12/10)*0.5+(C12/200)*0.3+(E12/10)*0.2,1),16) -> 1.1 | J12: Licensed
A13: Minecraft | B13: =COUNTIF('📋 Data & Predictions'!$B$4:$B$77,A13) -> 1 | C13: =IFERROR(IF(AVERAGEIF('📋 Data & Predictions'!$B$4:$B$77,A13,'📋 Data & Predictions'!$H$4:$H$77)=0,47.21,AVERAGEIF('📋 Data & Predictions'!$B$4:$B$77,A13,'📋 Data & Predictions'!$H$4:$H$77)),47.21) -> 109.99 | D13: =IFERROR(IF(AVERAGEIF('📋 Data & Predictions'!$B$4:$B$77,A13,'📋 Data & Predictions'!$E$4:$E$77)=0,485,AVERAGEIF('📋 Data & Predictions'!$B$4:$B$77,A13,'📋 Data & Predictions'!$E$4:$E$77)),485) -> 922 | E13: =IFERROR(IF(AVERAGEIF('📋 Data & Predictions'!$B$4:$B$77,A13,'📋 Data & Predictions'!$F$4:$F$77)=0,0.7,AVERAGEIF('📋 Data & Predictions'!$B$4:$B$77,A13,'📋 Data & Predictions'!$F$4:$F$77)),0.7) -> 0.7 | F13: =IFERROR(C13/D13,0) -> 0.11929501 | G13: =IFERROR(IF(AVERAGEIF('📋 Data & Predictions'!$B$4:$B$77,A13,'📋 Data & Predictions'!$I$4:$I$77)=0,67.84,AVERAGEIF('📋 Data & Predictions'!$B$4:$B$77,A13,'📋 Data & Predictions'!$I$4:$I$77)),67.84) -> 155.71 | H13: =IFERROR((G13-C13)/C13*100,0) -> 41.567415 | I13: =IFERROR(ROUND((H13/10)*0.5+(C13/200)*0.3+(E13/10)*0.2,1),16.8) -> 2.3 | J13: Licensed
A14: Star Wars | B14: =COUNTIF('📋 Data & Predictions'!$B$4:$B$77,A14) -> 12 | C14: =IFERROR(IF(AVERAGEIF('📋 Data & Predictions'!$B$4:$B$77,A14,'📋 Data & Predictions'!$H$4:$H$77)=0,46.84,AVERAGEIF('📋 Data & Predictions'!$B$4:$B$77,A14,'📋 Data & Predictions'!$H$4:$H$77)),46.84) -> 257.40667 | D14: =IFERROR(IF(AVERAGEIF('📋 Data & Predictions'!$B$4:$B$77,A14,'📋 Data & Predictions'!$E$4:$E$77)=0,430,AVERAGEIF('📋 Data & Predictions'!$B$4:$B$77,A14,'📋 Data & Predictions'!$E$4:$E$77)),430) -> 2472.5833 | E14: =IFERROR(IF(AVERAGEIF('📋 Data & Predictions'!$B$4:$B$77,A14,'📋 Data & Predictions'!$F$4:$F$77)=0,3,AVERAGEIF('📋 Data & Predictions'!$B$4:$B$77,A14,'📋 Data & Predictions'!$F$4:$F$77)),3) -> 7 | F14: =IFERROR(C14/D14,0) -> 0.10410434 | G14: =IFERROR(IF(AVERAGEIF('📋 Data & Predictions'!$B$4:$B$77,A14,'📋 Data & Predictions'!$I$4:$I$77)=0,100.92,AVERAGEIF('📋 Data & Predictions'!$B$4:$B$77,A14,'📋 Data & Predictions'!$I$4:$I$77)),100.92) -> 407.93083 | H14: =IFERROR((G14-C14)/C14*100,0) -> 58.477183 | I14: =IFERROR(ROUND((H14/10)*0.5+(C14/200)*0.3+(E14/10)*0.2,1),30.5) -> 3.4 | J14: Licensed/High ROI
A15: Dino | B15: =COUNTIF('📋 Data & Predictions'!$B$4:$B$77,A15) -> 0 | C15: =IFERROR(IF(AVERAGEIF('📋 Data & Predictions'!$B$4:$B$77,A15,'📋 Data & Predictions'!$H$4:$H$77)=0,45.28,AVERAGEIF('📋 Data & Predictions'!$B$4:$B$77,A15,'📋 Data & Predictions'!$H$4:$H$77)),45.28) -> 45.28 | D15: =IFERROR(IF(AVERAGEIF('📋 Data & Predictions'!$B$4:$B$77,A15,'📋 Data & Predictions'!$E$4:$E$77)=0,320,AVERAGEIF('📋 Data & Predictions'!$B$4:$B$77,A15,'📋 Data & Predictions'!$E$4:$E$77)),320) -> 320 | E15: =IFERROR(IF(AVERAGEIF('📋 Data & Predictions'!$B$4:$B$77,A15,'📋 Data & Predictions'!$F$4:$F$77)=0,2,AVERAGEIF('📋 Data & Predictions'!$B$4:$B$77,A15,'📋 Data & Predictions'!$F$4:$F$77)),2) -> 2 | F15: =IFERROR(C15/D15,0) -> 0.1415 | G15: =IFERROR(IF(AVERAGEIF('📋 Data & Predictions'!$B$4:$B$77,A15,'📋 Data & Predictions'!$I$4:$I$77)=0,108.72,AVERAGEIF('📋 Data & Predictions'!$B$4:$B$77,A15,'📋 Data & Predictions'!$I$4:$I$77)),108.72) -> 108.72 | H15: =IFERROR((G15-C15)/C15*100,0) -> 140.10601 | I15: =IFERROR(ROUND((H15/10)*0.5+(C15/200)*0.3+(E15/10)*0.2,1),26.4) -> 7.1 | J15: Mid-Tier
A16: Agents | B16: =COUNTIF('📋 Data & Predictions'!$B$4:$B$77,A16) -> 0 | C16: =IFERROR(IF(AVERAGEIF('📋 Data & Predictions'!$B$4:$B$77,A16,'📋 Data & Predictions'!$H$4:$H$77)=0,43.25,AVERAGEIF('📋 Data & Predictions'!$B$4:$B$77,A16,'📋 Data & Predictions'!$H$4:$H$77)),43.25) -> 43.25 | D16: =IFERROR(IF(AVERAGEIF('📋 Data & Predictions'!$B$4:$B$77,A16,'📋 Data & Predictions'!$E$4:$E$77)=0,440,AVERAGEIF('📋 Data & Predictions'!$B$4:$B$77,A16,'📋 Data & Predictions'!$E$4:$E$77)),440) -> 440 | E16: =IFERROR(IF(AVERAGEIF('📋 Data & Predictions'!$B$4:$B$77,A16,'📋 Data & Predictions'!$F$4:$F$77)=0,3.6,AVERAGEIF('📋 Data & Predictions'!$B$4:$B$77,A16,'📋 Data & Predictions'!$F$4:$F$77)),3.6) -> 3.6 | F16: =IFERROR(C16/D16,0) -> 0.098295455 | G16: =IFERROR(IF(AVERAGEIF('📋 Data & Predictions'!$B$4:$B$77,A16,'📋 Data & Predictions'!$I$4:$I$77)=0,78.91,AVERAGEIF('📋 Data & Predictions'!$B$4:$B$77,A16,'📋 Data & Predictions'!$I$4:$I$77)),78.91) -> 78.91 | H16: =IFERROR((G16-C16)/C16*100,0) -> 82.450867 | I16: =IFERROR(ROUND((H16/10)*0.5+(C16/200)*0.3+(E16/10)*0.2,1),19.3) -> 4.3 | J16: Mid-Tier
A17: The Lego Movie | B17: =COUNTIF('📋 Data & Predictions'!$B$4:$B$77,A17) -> 0 | C17: =IFERROR(IF(AVERAGEIF('📋 Data & Predictions'!$B$4:$B$77,A17,'📋 Data & Predictions'!$H$4:$H$77)=0,41.56,AVERAGEIF('📋 Data & Predictions'!$B$4:$B$77,A17,'📋 Data & Predictions'!$H$4:$H$77)),41.56) -> 41.56 | D17: =IFERROR(IF(AVERAGEIF('📋 Data & Predictions'!$B$4:$B$77,A17,'📋 Data & Predictions'!$E$4:$E$77)=0,461,AVERAGEIF('📋 Data & Predictions'!$B$4:$B$77,A17,'📋 Data & Predictions'!$E$4:$E$77)),461) -> 461 | E17: =IFERROR(IF(AVERAGEIF('📋 Data & Predictions'!$B$4:$B$77,A17,'📋 Data & Predictions'!$F$4:$F$77)=0,3.1,AVERAGEIF('📋 Data & Predictions'!$B$4:$B$77,A17,'📋 Data & Predictions'!$F$4:$F$77)),3.1) -> 3.1 | F17: =IFERROR(C17/D17,0) -> 0.090151844 | G17: =IFERROR(IF(AVERAGEIF('📋 Data & Predictions'!$B$4:$B$77,A17,'📋 Data & Predictions'!$I$4:$I$77)=0,45.5,AVERAGEIF('📋 Data & Predictions'!$B$4:$B$77,A17,'📋 Data & Predictions'!$I$4:$I$77)),45.5) -> 45.5 | H17: =IFERROR((G17-C17)/C17*100,0) -> 9.4802695 | I17: =IFERROR(ROUND((H17/10)*0.5+(C17/200)*0.3+(E17/10)*0.2,1),12) -> 0.6 | J17: Licensed
A18: Monster Fighters | B18: =COUNTIF('📋 Data & Predictions'!$B$4:$B$77,A18) -> 1 | C18: =IFERROR(IF(AVERAGEIF('📋 Data & Predictions'!$B$4:$B$77,A18,'📋 Data & Predictions'!$H$4:$H$77)=0,41.45,AVERAGEIF('📋 Data & Predictions'!$B$4:$B$77,A18,'📋 Data & Predictions'!$H$4:$H$77)),41.45) -> 179.99 | D18: =IFERROR(IF(AVERAGEIF('📋 Data & Predictions'!$B$4:$B$77,A18,'📋 Data & Predictions'!$E$4:$E$77)=0,422,AVERAGEIF('📋 Data & Predictions'!$B$4:$B$77,A18,'📋 Data & Predictions'!$E$4:$E$77)),422) -> 2064 | E18: =IFERROR(IF(AVERAGEIF('📋 Data & Predictions'!$B$4:$B$77,A18,'📋 Data & Predictions'!$F$4:$F$77)=0,2.9,AVERAGEIF('📋 Data & Predictions'!$B$4:$B$77,A18,'📋 Data & Predictions'!$F$4:$F$77)),2.9) -> 6 | F18: =IFERROR(C18/D18,0) -> 0.087204457 | G18: =IFERROR(IF(AVERAGEIF('📋 Data & Predictions'!$B$4:$B$77,A18,'📋 Data & Predictions'!$I$4:$I$77)=0,73.63,AVERAGEIF('📋 Data & Predictions'!$B$4:$B$77,A18,'📋 Data & Predictions'!$I$4:$I$77)),73.63) -> 304.13 | H18: =IFERROR((G18-C18)/C18*100,0) -> 68.970498 | I18: =IFERROR(ROUND((H18/10)*0.5+(C18/200)*0.3+(E18/10)*0.2,1),29.9) -> 3.8 | J18: High ROI
A19: Discovery | B19: =COUNTIF('📋 Data & Predictions'!$B$4:$B$77,A19) -> 0 | C19: =IFERROR(IF(AVERAGEIF('📋 Data & Predictions'!$B$4:$B$77,A19,'📋 Data & Predictions'!$H$4:$H$77)=0,40.82,AVERAGEIF('📋 Data & Predictions'!$B$4:$B$77,A19,'📋 Data & Predictions'!$H$4:$H$77)),40.82) -> 40.82 | D19: =IFERROR(IF(AVERAGEIF('📋 Data & Predictions'!$B$4:$B$77,A19,'📋 Data & Predictions'!$E$4:$E$77)=0,485,AVERAGEIF('📋 Data & Predictions'!$B$4:$B$77,A19,'📋 Data & Predictions'!$E$4:$E$77)),485) -> 485 | E19: =IFERROR(IF(AVERAGEIF('📋 Data & Predictions'!$B$4:$B$77,A19,'📋 Data & Predictions'!$F$4:$F$77)=0,0.3,AVERAGEIF('📋 Data & Predictions'!$B$4:$B$77,A19,'📋 Data & Predictions'!$F$4:$F$77)),0.3) -> 0.3 | F19: =IFERROR(C19/D19,0) -> 0.084164948 | G19: =IFERROR(IF(AVERAGEIF('📋 Data & Predictions'!$B$4:$B$77,A19,'📋 Data & Predictions'!$I$4:$I$77)=0,186.44,AVERAGEIF('📋 Data & Predictions'!$B$4:$B$77,A19,'📋 Data & Predictions'!$I$4:$I$77)),186.44) -> 186.44 | H19: =IFERROR((G19-C19)/C19*100,0) -> 356.73689 | I19: =IFERROR(ROUND((H19/10)*0.5+(C19/200)*0.3+(E19/10)*0.2,1),60.2) -> 17.9 | J19: Premium/High ROI
A20: Batman | B20: =COUNTIF('📋 Data & Predictions'!$B$4:$B$77,A20) -> 5 | C20: =IFERROR(IF(AVERAGEIF('📋 Data & Predictions'!$B$4:$B$77,A20,'📋 Data & Predictions'!$H$4:$H$77)=0,40.41,AVERAGEIF('📋 Data & Predictions'!$B$4:$B$77,A20,'📋 Data & Predictions'!$H$4:$H$77)),40.41) -> 89.99 | D20: =IFERROR(IF(AVERAGEIF('📋 Data & Predictions'!$B$4:$B$77,A20,'📋 Data & Predictions'!$E$4:$E$77)=0,411,AVERAGEIF('📋 Data & Predictions'!$B$4:$B$77,A20,'📋 Data & Predictions'!$E$4:$E$77)),411) -> 886.8 | E20: =IFERROR(IF(AVERAGEIF('📋 Data & Predictions'!$B$4:$B$77,A20,'📋 Data & Predictions'!$F$4:$F$77)=0,2.7,AVERAGEIF('📋 Data & Predictions'!$B$4:$B$77,A20,'📋 Data & Predictions'!$F$4:$F$77)),2.7) -> 3.4 | F20: =IFERROR(C20/D20,0) -> 0.10147722 | G20: =IFERROR(IF(AVERAGEIF('📋 Data & Predictions'!$B$4:$B$77,A20,'📋 Data & Predictions'!$I$4:$I$77)=0,132.93,AVERAGEIF('📋 Data & Predictions'!$B$4:$B$77,A20,'📋 Data & Predictions'!$I$4:$I$77)),132.93) -> 223.332 | H20: =IFERROR((G20-C20)/C20*100,0) -> 148.17424 | I20: =IFERROR(ROUND((H20/10)*0.5+(C20/200)*0.3+(E20/10)*0.2,1),39.4) -> 7.6 | J20: Licensed/High ROI
A21: Ideas | B21: =COUNTIF('📋 Data & Predictions'!$B$4:$B$77,A21) -> 0 | C21: =IFERROR(IF(AVERAGEIF('📋 Data & Predictions'!$B$4:$B$77,A21,'📋 Data & Predictions'!$H$4:$H$77)=0,38.12,AVERAGEIF('📋 Data & Predictions'!$B$4:$B$77,A21,'📋 Data & Predictions'!$H$4:$H$77)),38.12) -> 38.12 | D21: =IFERROR(IF(AVERAGEIF('📋 Data & Predictions'!$B$4:$B$77,A21,'📋 Data & Predictions'!$E$4:$E$77)=0,369,AVERAGEIF('📋 Data & Predictions'!$B$4:$B$77,A21,'📋 Data & Predictions'!$E$4:$E$77)),369) -> 369 | E21: =IFERROR(IF(AVERAGEIF('📋 Data & Predictions'!$B$4:$B$77,A21,'📋 Data & Predictions'!$F$4:$F$77)=0,1.5,AVERAGEIF('📋 Data & Predictions'!$B$4:$B$77,A21,'📋 Data & Predictions'!$F$4:$F$77)),1.5) -> 1.5 | F21: =IFERROR(C21/D21,0) -> 0.10330623 | G21: =IFERROR(IF(AVERAGEIF('📋 Data & Predictions'!$B$4:$B$77,A21,'📋 Data & Predictions'!$I$4:$I$77)=0,106.55,AVERAGEIF('📋 Data & Predictions'!$B$4:$B$77,A21,'📋 Data & Predictions'!$I$4:$I$77)),106.55) -> 106.55 | H21: =IFERROR((G21-C21)/C21*100,0) -> 179.51207 | I21: =IFERROR(ROUND((H21/10)*0.5+(C21/200)*0.3+(E21/10)*0.2,1),25.9) -> 9.1 | J21: Mid-Tier
A22: Indiana Jones | B22: =COUNTIF('📋 Data & Predictions'!$B$4:$B$77,A22) -> 2 | C22: =IFERROR(IF(AVERAGEIF('📋 Data & Predictions'!$B$4:$B$77,A22,'📋 Data & Predictions'!$H$4:$H$77)=0,37.55,AVERAGEIF('📋 Data & Predictions'!$B$4:$B$77,A22,'📋 Data & Predictions'!$H$4:$H$77)),37.55) -> 33.77 | D22: =IFERROR(IF(AVERAGEIF('📋 Data & Predictions'!$B$4:$B$77,A22,'📋 Data & Predictions'!$E$4:$E$77)=0,370,AVERAGEIF('📋 Data & Predictions'!$B$4:$B$77,A22,'📋 Data & Predictions'!$E$4:$E$77)),370) -> 307 | E22: =IFERROR(IF(AVERAGEIF('📋 Data & Predictions'!$B$4:$B$77,A22,'📋 Data & Predictions'!$F$4:$F$77)=0,4.6,AVERAGEIF('📋 Data & Predictions'!$B$4:$B$77,A22,'📋 Data & Predictions'!$F$4:$F$77)),4.6) -> 4.8 | F22: =IFERROR(C22/D22,0) -> 0.11 | G22: =IFERROR(IF(AVERAGEIF('📋 Data & Predictions'!$B$4:$B$77,A22,'📋 Data & Predictions'!$I$4:$I$77)=0,109.4,AVERAGEIF('📋 Data & Predictions'!$B$4:$B$77,A22,'📋 Data & Predictions'!$I$4:$I$77)),109.4) -> 101.735 | H22: =IFERROR((G22-C22)/C22*100,0) -> 201.25851 | I22: =IFERROR(ROUND((H22/10)*0.5+(C22/200)*0.3+(E22/10)*0.2,1),34.4) -> 10.2 | J22: Licensed/High ROI
A23: Lone Ranger | B23: =COUNTIF('📋 Data & Predictions'!$B$4:$B$77,A23) -> 0 | C23: =IFERROR(IF(AVERAGEIF('📋 Data & Predictions'!$B$4:$B$77,A23,'📋 Data & Predictions'!$H$4:$H$77)=0,36.49,AVERAGEIF('📋 Data & Predictions'!$B$4:$B$77,A23,'📋 Data & Predictions'!$H$4:$H$77)),36.49) -> 36.49 | D23: =IFERROR(IF(AVERAGEIF('📋 Data & Predictions'!$B$4:$B$77,A23,'📋 Data & Predictions'!$E$4:$E$77)=0,310,AVERAGEIF('📋 Data & Predictions'!$B$4:$B$77,A23,'📋 Data & Predictions'!$E$4:$E$77)),310) -> 310 | E23: =IFERROR(IF(AVERAGEIF('📋 Data & Predictions'!$B$4:$B$77,A23,'📋 Data & Predictions'!$F$4:$F$77)=0,3.9,AVERAGEIF('📋 Data & Predictions'!$B$4:$B$77,A23,'📋 Data & Predictions'!$F$4:$F$77)),3.9) -> 3.9 | F23: =IFERROR(C23/D23,0) -> 0.11770968 | G23: =IFERROR(IF(AVERAGEIF('📋 Data & Predictions'!$B$4:$B$77,A23,'📋 Data & Predictions'!$I$4:$I$77)=0,38.02,AVERAGEIF('📋 Data & Predictions'!$B$4:$B$77,A23,'📋 Data & Predictions'!$I$4:$I$77)),38.02) -> 38.02 | H23: =IFERROR((G23-C23)/C23*100,0) -> 4.1929296 | I23: =IFERROR(ROUND((H23/10)*0.5+(C23/200)*0.3+(E23/10)*0.2,1),13.3) -> 0.3 | J23: Licensed
A24: Pirates of Caribbean | B24: =COUNTIF('📋 Data & Predictions'!$B$4:$B$77,A24) -> 0 | C24: =IFERROR(IF(AVERAGEIF('📋 Data & Predictions'!$B$4:$B$77,A24,'📋 Data & Predictions'!$H$4:$H$77)=0,35.85,AVERAGEIF('📋 Data & Predictions'!$B$4:$B$77,A24,'📋 Data & Predictions'!$H$4:$H$77)),35.85) -> 35.85 | D24: =IFERROR(IF(AVERAGEIF('📋 Data & Predictions'!$B$4:$B$77,A24,'📋 Data & Predictions'!$E$4:$E$77)=0,302,AVERAGEIF('📋 Data & Predictions'!$B$4:$B$77,A24,'📋 Data & Predictions'!$E$4:$E$77)),302) -> 302 | E24: =IFERROR(IF(AVERAGEIF('📋 Data & Predictions'!$B$4:$B$77,A24,'📋 Data & Predictions'!$F$4:$F$77)=0,3.6,AVERAGEIF('📋 Data & Predictions'!$B$4:$B$77,A24,'📋 Data & Predictions'!$F$4:$F$77)),3.6) -> 3.6 | F24: =IFERROR(C24/D24,0) -> 0.11870861 | G24: =IFERROR(IF(AVERAGEIF('📋 Data & Predictions'!$B$4:$B$77,A24,'📋 Data & Predictions'!$I$4:$I$77)=0,67.12,AVERAGEIF('📋 Data & Predictions'!$B$4:$B$77,A24,'📋 Data & Predictions'!$I$4:$I$77)),67.12) -> 67.12 | H24: =IFERROR((G24-C24)/C24*100,0) -> 87.224547 | I24: =IFERROR(ROUND((H24/10)*0.5+(C24/200)*0.3+(E24/10)*0.2,1),22.5) -> 4.5 | J24: Licensed
A25: Power Miners | B25: =COUNTIF('📋 Data & Predictions'!$B$4:$B$77,A25) -> 0 | C25: =IFERROR(IF(AVERAGEIF('📋 Data & Predictions'!$B$4:$B$77,A25,'📋 Data & Predictions'!$H$4:$H$77)=0,35.68,AVERAGEIF('📋 Data & Predictions'!$B$4:$B$77,A25,'📋 Data & Predictions'!$H$4:$H$77)),35.68) -> 35.68 | D25: =IFERROR(IF(AVERAGEIF('📋 Data & Predictions'!$B$4:$B$77,A25,'📋 Data & Predictions'!$E$4:$E$77)=0,267,AVERAGEIF('📋 Data & Predictions'!$B$4:$B$77,A25,'📋 Data & Predictions'!$E$4:$E$77)),267) -> 267 | E25: =IFERROR(IF(AVERAGEIF('📋 Data & Predictions'!$B$4:$B$77,A25,'📋 Data & Predictions'!$F$4:$F$77)=0,2.7,AVERAGEIF('📋 Data & Predictions'!$B$4:$B$77,A25,'📋 Data & Predictions'!$F$4:$F$77)),2.7) -> 2.7 | F25: =IFERROR(C25/D25,0) -> 0.13363296 | G25: =IFERROR(IF(AVERAGEIF('📋 Data & Predictions'!$B$4:$B$77,A25,'📋 Data & Predictions'!$I$4:$I$77)=0,83.83,AVERAGEIF('📋 Data & Predictions'!$B$4:$B$77,A25,'📋 Data & Predictions'!$I$4:$I$77)),83.83) -> 83.83 | H25: =IFERROR((G25-C25)/C25*100,0) -> 134.94955 | I25: =IFERROR(ROUND((H25/10)*0.5+(C25/200)*0.3+(E25/10)*0.2,1),26.2) -> 6.9 | J25: Mid-Tier
A26: Harry Potter | B26: =COUNTIF('📋 Data & Predictions'!$B$4:$B$77,A26) -> 3 | C26: =IFERROR(IF(AVERAGEIF('📋 Data & Predictions'!$B$4:$B$77,A26,'📋 Data & Predictions'!$H$4:$H$77)=0,34.99,AVERAGEIF('📋 Data & Predictions'!$B$4:$B$77,A26,'📋 Data & Predictions'!$H$4:$H$77)),34.99) -> 133.32333 | D26: =IFERROR(IF(AVERAGEIF('📋 Data & Predictions'!$B$4:$B$77,A26,'📋 Data & Predictions'!$E$4:$E$77)=0,327,AVERAGEIF('📋 Data & Predictions'!$B$4:$B$77,A26,'📋 Data & Predictions'!$E$4:$E$77)),327) -> 1341 | E26: =IFERROR(IF(AVERAGEIF('📋 Data & Predictions'!$B$4:$B$77,A26,'📋 Data & Predictions'!$F$4:$F$77)=0,3.6,AVERAGEIF('📋 Data & Predictions'!$B$4:$B$77,A26,'📋 Data & Predictions'!$F$4:$F$77)),3.6) -> 9 | F26: =IFERROR(C26/D26,0) -> 0.09942083 | G26: =IFERROR(IF(AVERAGEIF('📋 Data & Predictions'!$B$4:$B$77,A26,'📋 Data & Predictions'!$I$4:$I$77)=0,126.7,AVERAGEIF('📋 Data & Predictions'!$B$4:$B$77,A26,'📋 Data & Predictions'!$I$4:$I$77)),126.7) -> 375.83333 | H26: =IFERROR((G26-C26)/C26*100,0) -> 181.89614 | I26: =IFERROR(ROUND((H26/10)*0.5+(C26/200)*0.3+(E26/10)*0.2,1),40) -> 9.5 | J26: Licensed/High ROI
A27: Pirates | B27: =COUNTIF('📋 Data & Predictions'!$B$4:$B$77,A27) -> 3 | C27: =IFERROR(IF(AVERAGEIF('📋 Data & Predictions'!$B$4:$B$77,A27,'📋 Data & Predictions'!$H$4:$H$77)=0,34.84,AVERAGEIF('📋 Data & Predictions'!$B$4:$B$77,A27,'📋 Data & Predictions'!$H$4:$H$77)),34.84) -> 138.99 | D27: =IFERROR(IF(AVERAGEIF('📋 Data & Predictions'!$B$4:$B$77,A27,'📋 Data & Predictions'!$E$4:$E$77)=0,243,AVERAGEIF('📋 Data & Predictions'!$B$4:$B$77,A27,'📋 Data & Predictions'!$E$4:$E$77)),243) -> 1161.6667 | E27: =IFERROR(IF(AVERAGEIF('📋 Data & Predictions'!$B$4:$B$77,A27,'📋 Data & Predictions'!$F$4:$F$77)=0,4.1,AVERAGEIF('📋 Data & Predictions'!$B$4:$B$77,A27,'📋 Data & Predictions'!$F$4:$F$77)),4.1) -> 8.6666667 | F27: =IFERROR(C27/D27,0) -> 0.11964706 | G27: =IFERROR(IF(AVERAGEIF('📋 Data & Predictions'!$B$4:$B$77,A27,'📋 Data & Predictions'!$I$4:$I$77)=0,129.03,AVERAGEIF('📋 Data & Predictions'!$B$4:$B$77,A27,'📋 Data & Predictions'!$I$4:$I$77)),129.03) -> 534.63333 | H27: =IFERROR((G27-C27)/C27*100,0) -> 284.65597 | I27: =IFERROR(ROUND((H27/10)*0.5+(C27/200)*0.3+(E27/10)*0.2,1),40.6) -> 14.6 | J27: Classic/High ROI
A28: City | B28: =COUNTIF('📋 Data & Predictions'!$B$4:$B$77,A28) -> 5 | C28: =IFERROR(IF(AVERAGEIF('📋 Data & Predictions'!$B$4:$B$77,A28,'📋 Data & Predictions'!$H$4:$H$77)=0,34.67,AVERAGEIF('📋 Data & Predictions'!$B$4:$B$77,A28,'📋 Data & Predictions'!$H$4:$H$77)),34.67) -> 134.99 | D28: =IFERROR(IF(AVERAGEIF('📋 Data & Predictions'!$B$4:$B$77,A28,'📋 Data & Predictions'!$E$4:$E$77)=0,267,AVERAGEIF('📋 Data & Predictions'!$B$4:$B$77,A28,'📋 Data & Predictions'!$E$4:$E$77)),267) -> 651 | E28: =IFERROR(IF(AVERAGEIF('📋 Data & Predictions'!$B$4:$B$77,A28,'📋 Data & Predictions'!$F$4:$F$77)=0,2.6,AVERAGEIF('📋 Data & Predictions'!$B$4:$B$77,A28,'📋 Data & Predictions'!$F$4:$F$77)),2.6) -> 3.8 | F28: =IFERROR(C28/D28,0) -> 0.20735791 | G28: =IFERROR(IF(AVERAGEIF('📋 Data & Predictions'!$B$4:$B$77,A28,'📋 Data & Predictions'!$I$4:$I$77)=0,64.06,AVERAGEIF('📋 Data & Predictions'!$B$4:$B$77,A28,'📋 Data & Predictions'!$I$4:$I$77)),64.06) -> 157.112 | H28: =IFERROR((G28-C28)/C28*100,0) -> 16.387881 | I28: =IFERROR(ROUND((H28/10)*0.5+(C28/200)*0.3+(E28/10)*0.2,1),19.9) -> 1.1 | J28: Mainstream
A29: TMNT | B29: =COUNTIF('📋 Data & Predictions'!$B$4:$B$77,A29) -> 0 | C29: =IFERROR(IF(AVERAGEIF('📋 Data & Predictions'!$B$4:$B$77,A29,'📋 Data & Predictions'!$H$4:$H$77)=0,33.88,AVERAGEIF('📋 Data & Predictions'!$B$4:$B$77,A29,'📋 Data & Predictions'!$H$4:$H$77)),33.88) -> 33.88 | D29: =IFERROR(IF(AVERAGEIF('📋 Data & Predictions'!$B$4:$B$77,A29,'📋 Data & Predictions'!$E$4:$E$77)=0,321,AVERAGEIF('📋 Data & Predictions'!$B$4:$B$77,A29,'📋 Data & Predictions'!$E$4:$E$77)),321) -> 321 | E29: =IFERROR(IF(AVERAGEIF('📋 Data & Predictions'!$B$4:$B$77,A29,'📋 Data & Predictions'!$F$4:$F$77)=0,3.5,AVERAGEIF('📋 Data & Predictions'!$B$4:$B$77,A29,'📋 Data & Predictions'!$F$4:$F$77)),3.5) -> 3.5 | F29: =IFERROR(C29/D29,0) -> 0.10554517 | G29: =IFERROR(IF(AVERAGEIF('📋 Data & Predictions'!$B$4:$B$77,A29,'📋 Data & Predictions'!$I$4:$I$77)=0,34.96,AVERAGEIF('📋 Data & Predictions'!$B$4:$B$77,A29,'📋 Data & Predictions'!$I$4:$I$77)),34.96) -> 34.96 | H29: =IFERROR((G29-C29)/C29*100,0) -> 3.1877214 | I29: =IFERROR(ROUND((H29/10)*0.5+(C29/200)*0.3+(E29/10)*0.2,1),9.3) -> 0.3 | J29: Licensed
A30: Space | B30: =COUNTIF('📋 Data & Predictions'!$B$4:$B$77,A30) -> 0 | C30: =IFERROR(IF(AVERAGEIF('📋 Data & Predictions'!$B$4:$B$77,A30,'📋 Data & Predictions'!$H$4:$H$77)=0,33.56,AVERAGEIF('📋 Data & Predictions'!$B$4:$B$77,A30,'📋 Data & Predictions'!$H$4:$H$77)),33.56) -> 33.56 | D30: =IFERROR(IF(AVERAGEIF('📋 Data & Predictions'!$B$4:$B$77,A30,'📋 Data & Predictions'!$E$4:$E$77)=0,304,AVERAGEIF('📋 Data & Predictions'!$B$4:$B$77,A30,'📋 Data & Predictions'!$E$4:$E$77)),304) -> 304 | E30: =IFERROR(IF(AVERAGEIF('📋 Data & Predictions'!$B$4:$B$77,A30,'📋 Data & Predictions'!$F$4:$F$77)=0,2.8,AVERAGEIF('📋 Data & Predictions'!$B$4:$B$77,A30,'📋 Data & Predictions'!$F$4:$F$77)),2.8) -> 2.8 | F30: =IFERROR(C30/D30,0) -> 0.11039474 | G30: =IFERROR(IF(AVERAGEIF('📋 Data & Predictions'!$B$4:$B$77,A30,'📋 Data & Predictions'!$I$4:$I$77)=0,45.73,AVERAGEIF('📋 Data & Predictions'!$B$4:$B$77,A30,'📋 Data & Predictions'!$I$4:$I$77)),45.73) -> 45.73 | H30: =IFERROR((G30-C30)/C30*100,0) -> 36.263409 | I30: =IFERROR(ROUND((H30/10)*0.5+(C30/200)*0.3+(E30/10)*0.2,1),16.1) -> 1.9 | J30: Classic
A31: Prince of Persia | B31: =COUNTIF('📋 Data & Predictions'!$B$4:$B$77,A31) -> 0 | C31: =IFERROR(IF(AVERAGEIF('📋 Data & Predictions'!$B$4:$B$77,A31,'📋 Data & Predictions'!$H$4:$H$77)=0,32.49,AVERAGEIF('📋 Data & Predictions'!$B$4:$B$77,A31,'📋 Data & Predictions'!$H$4:$H$77)),32.49) -> 32.49 | D31: =IFERROR(IF(AVERAGEIF('📋 Data & Predictions'!$B$4:$B$77,A31,'📋 Data & Predictions'!$E$4:$E$77)=0,312,AVERAGEIF('📋 Data & Predictions'!$B$4:$B$77,A31,'📋 Data & Predictions'!$E$4:$E$77)),312) -> 312 | E31: =IFERROR(IF(AVERAGEIF('📋 Data & Predictions'!$B$4:$B$77,A31,'📋 Data & Predictions'!$F$4:$F$77)=0,3.8,AVERAGEIF('📋 Data & Predictions'!$B$4:$B$77,A31,'📋 Data & Predictions'!$F$4:$F$77)),3.8) -> 3.8 | F31: =IFERROR(C31/D31,0) -> 0.10413462 | G31: =IFERROR(IF(AVERAGEIF('📋 Data & Predictions'!$B$4:$B$77,A31,'📋 Data & Predictions'!$I$4:$I$77)=0,29.28,AVERAGEIF('📋 Data & Predictions'!$B$4:$B$77,A31,'📋 Data & Predictions'!$I$4:$I$77)),29.28) -> 29.28 | H31: =IFERROR((G31-C31)/C31*100,0) -> -9.8799631 | I31: =IFERROR(ROUND((H31/10)*0.5+(C31/200)*0.3+(E31/10)*0.2,1),9.1) -> -0.4 | J31: Licensed
A32: Super Heroes | B32: =COUNTIF('📋 Data & Predictions'!$B$4:$B$77,A32) -> 1 | C32: =IFERROR(IF(AVERAGEIF('📋 Data & Predictions'!$B$4:$B$77,A32,'📋 Data & Predictions'!$H$4:$H$77)=0,31.3,AVERAGEIF('📋 Data & Predictions'!$B$4:$B$77,A32,'📋 Data & Predictions'!$H$4:$H$77)),31.3) -> 31.3 | D32: =IFERROR(IF(AVERAGEIF('📋 Data & Predictions'!$B$4:$B$77,A32,'📋 Data & Predictions'!$E$4:$E$77)=0,160,AVERAGEIF('📋 Data & Predictions'!$B$4:$B$77,A32,'📋 Data & Predictions'!$E$4:$E$77)),160) -> 160 | E32: =IFERROR(IF(AVERAGEIF('📋 Data & Predictions'!$B$4:$B$77,A32,'📋 Data & Predictions'!$F$4:$F$77)=0,2.1,AVERAGEIF('📋 Data & Predictions'!$B$4:$B$77,A32,'📋 Data & Predictions'!$F$4:$F$77)),2.1) -> 2 | F32: =IFERROR(C32/D32,0) -> 0.195625 | G32: =IFERROR(IF(AVERAGEIF('📋 Data & Predictions'!$B$4:$B$77,A32,'📋 Data & Predictions'!$I$4:$I$77)=0,44.72,AVERAGEIF('📋 Data & Predictions'!$B$4:$B$77,A32,'📋 Data & Predictions'!$I$4:$I$77)),44.72) -> 180 | H32: =IFERROR((G32-C32)/C32*100,0) -> 475.07987 | I32: =IFERROR(ROUND((H32/10)*0.5+(C32/200)*0.3+(E32/10)*0.2,1),55.7) -> 23.8 | J32: Licensed/High ROI
A33: SpongeBob | B33: =COUNTIF('📋 Data & Predictions'!$B$4:$B$77,A33) -> 0 | C33: =IFERROR(IF(AVERAGEIF('📋 Data & Predictions'!$B$4:$B$77,A33,'📋 Data & Predictions'!$H$4:$H$77)=0,30.35,AVERAGEIF('📋 Data & Predictions'!$B$4:$B$77,A33,'📋 Data & Predictions'!$H$4:$H$77)),30.35) -> 30.35 | D33: =IFERROR(IF(AVERAGEIF('📋 Data & Predictions'!$B$4:$B$77,A33,'📋 Data & Predictions'!$E$4:$E$77)=0,313,AVERAGEIF('📋 Data & Predictions'!$B$4:$B$77,A33,'📋 Data & Predictions'!$E$4:$E$77)),313) -> 313 | E33: =IFERROR(IF(AVERAGEIF('📋 Data & Predictions'!$B$4:$B$77,A33,'📋 Data & Predictions'!$F$4:$F$77)=0,2.9,AVERAGEIF('📋 Data & Predictions'!$B$4:$B$77,A33,'📋 Data & Predictions'!$F$4:$F$77)),2.9) -> 2.9 | F33: =IFERROR(C33/D33,0) -> 0.096964856 | G33: =IFERROR(IF(AVERAGEIF('📋 Data & Predictions'!$B$4:$B$77,A33,'📋 Data & Predictions'!$I$4:$I$77)=0,82.09,AVERAGEIF('📋 Data & Predictions'!$B$4:$B$77,A33,'📋 Data & Predictions'!$I$4:$I$77)),82.09) -> 82.09 | H33: =IFERROR((G33-C33)/C33*100,0) -> 170.47776 | I33: =IFERROR(ROUND((H33/10)*0.5+(C33/200)*0.3+(E33/10)*0.2,1),25.6) -> 8.6 | J33: Licensed
A34: Disney Princess | B34: =COUNTIF('📋 Data & Predictions'!$B$4:$B$77,A34) -> 0 | C34: =IFERROR(IF(AVERAGEIF('📋 Data & Predictions'!$B$4:$B$77,A34,'📋 Data & Predictions'!$H$4:$H$77)=0,29.7,AVERAGEIF('📋 Data & Predictions'!$B$4:$B$77,A34,'📋 Data & Predictions'!$H$4:$H$77)),29.7) -> 29.7 | D34: =IFERROR(IF(AVERAGEIF('📋 Data & Predictions'!$B$4:$B$77,A34,'📋 Data & Predictions'!$E$4:$E$77)=0,247,AVERAGEIF('📋 Data & Predictions'!$B$4:$B$77,A34,'📋 Data & Predictions'!$E$4:$E$77)),247) -> 247 | E34: =IFERROR(IF(AVERAGEIF('📋 Data & Predictions'!$B$4:$B$77,A34,'📋 Data & Predictions'!$F$4:$F$77)=0,1.4,AVERAGEIF('📋 Data & Predictions'!$B$4:$B$77,A34,'📋 Data & Predictions'!$F$4:$F$77)),1.4) -> 1.4 | F34: =IFERROR(C34/D34,0) -> 0.12024291 | G34: =IFERROR(IF(AVERAGEIF('📋 Data & Predictions'!$B$4:$B$77,A34,'📋 Data & Predictions'!$I$4:$I$77)=0,32.04,AVERAGEIF('📋 Data & Predictions'!$B$4:$B$77,A34,'📋 Data & Predictions'!$I$4:$I$77)),32.04) -> 32.04 | H34: =IFERROR((G34-C34)/C34*100,0) -> 7.8787879 | I34: =IFERROR(ROUND((H34/10)*0.5+(C34/200)*0.3+(E34/10)*0.2,1),9.2) -> 0.5 | J34: Licensed
A35: Spider-Man | B35: =COUNTIF('📋 Data & Predictions'!$B$4:$B$77,A35) -> 1 | C35: =IFERROR(IF(AVERAGEIF('📋 Data & Predictions'!$B$4:$B$77,A35,'📋 Data & Predictions'!$H$4:$H$77)=0,28.74,AVERAGEIF('📋 Data & Predictions'!$B$4:$B$77,A35,'📋 Data & Predictions'!$H$4:$H$77)),28.74) -> 28.74 | D35: =IFERROR(IF(AVERAGEIF('📋 Data & Predictions'!$B$4:$B$77,A35,'📋 Data & Predictions'!$E$4:$E$77)=0,255,AVERAGEIF('📋 Data & Predictions'!$B$4:$B$77,A35,'📋 Data & Predictions'!$E$4:$E$77)),255) -> 255 | E35: =IFERROR(IF(AVERAGEIF('📋 Data & Predictions'!$B$4:$B$77,A35,'📋 Data & Predictions'!$F$4:$F$77)=0,4.2,AVERAGEIF('📋 Data & Predictions'!$B$4:$B$77,A35,'📋 Data & Predictions'!$F$4:$F$77)),4.2) -> 4.2 | F35: =IFERROR(C35/D35,0) -> 0.11270588 | G35: =IFERROR(IF(AVERAGEIF('📋 Data & Predictions'!$B$4:$B$77,A35,'📋 Data & Predictions'!$I$4:$I$77)=0,94.42,AVERAGEIF('📋 Data & Predictions'!$B$4:$B$77,A35,'📋 Data & Predictions'!$I$4:$I$77)),94.42) -> 94.42 | H35: =IFERROR((G35-C35)/C35*100,0) -> 228.53166 | I35: =IFERROR(ROUND((H35/10)*0.5+(C35/200)*0.3+(E35/10)*0.2,1),34.9) -> 11.6 | J35: Licensed/High ROI
A36: Cars | B36: =COUNTIF('📋 Data & Predictions'!$B$4:$B$77,A36) -> 0 | C36: =IFERROR(IF(AVERAGEIF('📋 Data & Predictions'!$B$4:$B$77,A36,'📋 Data & Predictions'!$H$4:$H$77)=0,28.08,AVERAGEIF('📋 Data & Predictions'!$B$4:$B$77,A36,'📋 Data & Predictions'!$H$4:$H$77)),28.08) -> 28.08 | D36: =IFERROR(IF(AVERAGEIF('📋 Data & Predictions'!$B$4:$B$77,A36,'📋 Data & Predictions'!$E$4:$E$77)=0,247,AVERAGEIF('📋 Data & Predictions'!$B$4:$B$77,A36,'📋 Data & Predictions'!$E$4:$E$77)),247) -> 247 | E36: =IFERROR(IF(AVERAGEIF('📋 Data & Predictions'!$B$4:$B$77,A36,'📋 Data & Predictions'!$F$4:$F$77)=0,0,AVERAGEIF('📋 Data & Predictions'!$B$4:$B$77,A36,'📋 Data & Predictions'!$F$4:$F$77)),0) -> 0 | F36: =IFERROR(C36/D36,0) -> 0.11368421 | G36: =IFERROR(IF(AVERAGEIF('📋 Data & Predictions'!$B$4:$B$77,A36,'📋 Data & Predictions'!$I$4:$I$77)=0,40.17,AVERAGEIF('📋 Data & Predictions'!$B$4:$B$77,A36,'📋 Data & Predictions'!$I$4:$I$77)),40.17) -> 40.17 | H36: =IFERROR((G36-C36)/C36*100,0) -> 43.055556 | I36: =IFERROR(ROUND((H36/10)*0.5+(C36/200)*0.3+(E36/10)*0.2,1),14.3) -> 2.2 | J36: Licensed
A37: Toy Story | B37: =COUNTIF('📋 Data & Predictions'!$B$4:$B$77,A37) -> 0 | C37: =IFERROR(IF(AVERAGEIF('📋 Data & Predictions'!$B$4:$B$77,A37,'📋 Data & Predictions'!$H$4:$H$77)=0,27.19,AVERAGEIF('📋 Data & Predictions'!$B$4:$B$77,A37,'📋 Data & Predictions'!$H$4:$H$77)),27.19) -> 27.19 | D37: =IFERROR(IF(AVERAGEIF('📋 Data & Predictions'!$B$4:$B$77,A37,'📋 Data & Predictions'!$E$4:$E$77)=0,206,AVERAGEIF('📋 Data & Predictions'!$B$4:$B$77,A37,'📋 Data & Predictions'!$E$4:$E$77)),206) -> 206 | E37: =IFERROR(IF(AVERAGEIF('📋 Data & Predictions'!$B$4:$B$77,A37,'📋 Data & Predictions'!$F$4:$F$77)=0,2.7,AVERAGEIF('📋 Data & Predictions'!$B$4:$B$77,A37,'📋 Data & Predictions'!$F$4:$F$77)),2.7) -> 2.7 | F37: =IFERROR(C37/D37,0) -> 0.13199029 | G37: =IFERROR(IF(AVERAGEIF('📋 Data & Predictions'!$B$4:$B$77,A37,'📋 Data & Predictions'!$I$4:$I$77)=0,34.72,AVERAGEIF('📋 Data & Predictions'!$B$4:$B$77,A37,'📋 Data & Predictions'!$I$4:$I$77)),34.72) -> 34.72 | H37: =IFERROR((G37-C37)/C37*100,0) -> 27.694005 | I37: =IFERROR(ROUND((H37/10)*0.5+(C37/200)*0.3+(E37/10)*0.2,1),11.7) -> 1.5 | J37: Licensed
A38: Atlantis | B38: =COUNTIF('📋 Data & Predictions'!$B$4:$B$77,A38) -> 0 | C38: =IFERROR(IF(AVERAGEIF('📋 Data & Predictions'!$B$4:$B$77,A38,'📋 Data & Predictions'!$H$4:$H$77)=0,26.8,AVERAGEIF('📋 Data & Predictions'!$B$4:$B$77,A38,'📋 Data & Predictions'!$H$4:$H$77)),26.8) -> 26.8 | D38: =IFERROR(IF(AVERAGEIF('📋 Data & Predictions'!$B$4:$B$77,A38,'📋 Data & Predictions'!$E$4:$E$77)=0,248,AVERAGEIF('📋 Data & Predictions'!$B$4:$B$77,A38,'📋 Data & Predictions'!$E$4:$E$77)),248) -> 248 | E38: =IFERROR(IF(AVERAGEIF('📋 Data & Predictions'!$B$4:$B$77,A38,'📋 Data & Predictions'!$F$4:$F$77)=0,2,AVERAGEIF('📋 Data & Predictions'!$B$4:$B$77,A38,'📋 Data & Predictions'!$F$4:$F$77)),2) -> 2 | F38: =IFERROR(C38/D38,0) -> 0.10806452 | G38: =IFERROR(IF(AVERAGEIF('📋 Data & Predictions'!$B$4:$B$77,A38,'📋 Data & Predictions'!$I$4:$I$77)=0,29.2,AVERAGEIF('📋 Data & Predictions'!$B$4:$B$77,A38,'📋 Data & Predictions'!$I$4:$I$77)),29.2) -> 29.2 | H38: =IFERROR((G38-C38)/C38*100,0) -> 8.9552239 | I38: =IFERROR(ROUND((H38/10)*0.5+(C38/200)*0.3+(E38/10)*0.2,1),10.3) -> 0.5 | J38: Mid-Tier
A39: Legends of China | B39: =COUNTIF('📋 Data & Predictions'!$B$4:$B$77,A39) -> 1 | C39: =IFERROR(IF(AVERAGEIF('📋 Data & Predictions'!$B$4:$B$77,A39,'📋 Data & Predictions'!$H$4:$H$77)=0,26.57,AVERAGEIF('📋 Data & Predictions'!$B$4:$B$77,A39,'📋 Data & Predictions'!$H$4:$H$77)),26.57) -> 119.99 | D39: =IFERROR(IF(AVERAGEIF('📋 Data & Predictions'!$B$4:$B$77,A39,'📋 Data & Predictions'!$E$4:$E$77)=0,217,AVERAGEIF('📋 Data & Predictions'!$B$4:$B$77,A39,'📋 Data & Predictions'!$E$4:$E$77)),217) -> 1301 | E39: =IFERROR(IF(AVERAGEIF('📋 Data & Predictions'!$B$4:$B$77,A39,'📋 Data & Predictions'!$F$4:$F$77)=0,1.9,AVERAGEIF('📋 Data & Predictions'!$B$4:$B$77,A39,'📋 Data & Predictions'!$F$4:$F$77)),1.9) -> 7 | F39: =IFERROR(C39/D39,0) -> 0.092229055 | G39: =IFERROR(IF(AVERAGEIF('📋 Data & Predictions'!$B$4:$B$77,A39,'📋 Data & Predictions'!$I$4:$I$77)=0,32.73,AVERAGEIF('📋 Data & Predictions'!$B$4:$B$77,A39,'📋 Data & Predictions'!$I$4:$I$77)),32.73) -> 108 | H39: =IFERROR((G39-C39)/C39*100,0) -> -9.9924994 | I39: =IFERROR(ROUND((H39/10)*0.5+(C39/200)*0.3+(E39/10)*0.2,1),9.9) -> -0.2 | J39: Mainstream
A40: Ninjago | B40: =COUNTIF('📋 Data & Predictions'!$B$4:$B$77,A40) -> 3 | C40: =IFERROR(IF(AVERAGEIF('📋 Data & Predictions'!$B$4:$B$77,A40,'📋 Data & Predictions'!$H$4:$H$77)=0,25.63,AVERAGEIF('📋 Data & Predictions'!$B$4:$B$77,A40,'📋 Data & Predictions'!$H$4:$H$77)),25.63) -> 119.99 | D40: =IFERROR(IF(AVERAGEIF('📋 Data & Predictions'!$B$4:$B$77,A40,'📋 Data & Predictions'!$E$4:$E$77)=0,199,AVERAGEIF('📋 Data & Predictions'!$B$4:$B$77,A40,'📋 Data & Predictions'!$E$4:$E$77)),199) -> 1106 | E40: =IFERROR(IF(AVERAGEIF('📋 Data & Predictions'!$B$4:$B$77,A40,'📋 Data & Predictions'!$F$4:$F$77)=0,2.1,AVERAGEIF('📋 Data & Predictions'!$B$4:$B$77,A40,'📋 Data & Predictions'!$F$4:$F$77)),2.1) -> 7.6666667 | F40: =IFERROR(C40/D40,0) -> 0.10849005 | G40: =IFERROR(IF(AVERAGEIF('📋 Data & Predictions'!$B$4:$B$77,A40,'📋 Data & Predictions'!$I$4:$I$77)=0,39.24,AVERAGEIF('📋 Data & Predictions'!$B$4:$B$77,A40,'📋 Data & Predictions'!$I$4:$I$77)),39.24) -> 130.01333 | H40: =IFERROR((G40-C40)/C40*100,0) -> 8.3534739 | I40: =IFERROR(ROUND((H40/10)*0.5+(C40/200)*0.3+(E40/10)*0.2,1),14.3) -> 0.8 | J40: Mainstream
...

Sheet 🧮 Price Calculator
A1: 🧱 LEGO SET RETAIL PRICE CALCULATOR — OLS Regression Model
A2: Enter your set specifications below. The model predicts retail price using: Pieces, Minifigures, Size Group, and Theme ID.
A4: 📥 INPUT PARAMETERS (Change highlighted yellow cells)
A5: Number of Pieces | B5: 500 | C5: pieces | D5: Main price driver — piece count
A6: Number of Minifigures | B6: 5 | C6: figures | D6: Character count in set
A7: Size Group (1=Biggest, 4=Smallest) | B7: 2 | C7: 1–4 scale | D7: 1=Large, 2=Med-Large, 3=Med, 4=Small
A8: Theme Encoding ID | B8: 35 | C8: 0–43 | D8: Use Theme Lookup in 'Theme Analysis' sheet
A10: 📤 PREDICTED OUTPUTS (Auto-calculated)
A11: Predicted Retail Price ($) | B11: =$B$30+($B$31*B5)+($B$32*B6)+($B$33*B7)+($B$34*B8) -> 66.1394 | C11: ← Primary model output
A12: Suggested Price (Rounded to $5) | B12: =ROUND(B11/5,0)*5 -> 65 | C12: ← Retail pricing convention
A13: Price per Piece ($) | B13: =IF(B5>0,B11/B5,0) -> 0.1322788 | C13: ← Industry: $0.06–$0.12 mass market
A14: Price Band — Low ($) | B14: =B11*0.9 -> 59.52546 | C14: ← –10% confidence band
A15: Price Band — High ($) | B15: =B11*1.1 -> 72.75334 | C15: ← +10% confidence band
A16: Value Tier | B16: =IF(B11<20,"ENTRY (<$20)",IF(B11<50,"VALUE ($20-$49)",IF(B11<100,"MID ($50-$99)",IF(B11<150,"MID-HIGH ($100-$149)","PREMIUM ($150+)")))) -> MID ($50-$99)
A18: FORMULA: Price = 35.3652 + (0.0695×Pieces) + (1.6686×Minifigs) + (–8.1964×SizeGroup) + (0.1164×ThemeID)
A30: B0_Intercept | B30: 35.3652
A31: B1_Pieces | B31: 0.0695
A32: B2_Minifigs | B32: 1.6686
A33: B3_SizeGroup | B33: -8.1964
A34: B4_Theme | B34: 0.1164

Sheet 📋 Data & Predictions
A1: FULL DATASET — MODEL PREDICTIONS & RESIDUAL ANALYSIS (2,322 Sets)
A2: ℹ Use the AutoFilter (▼) to filter by Theme, Year, Value Flag, or any column. Color: 🟩 UNDERPRICED 🟥 OVERPRICED 🟨 FAIR VALUE
A3: Set ID | B3: Theme | C3: Set Name | D3: Year | E3: Pieces | F3: Minifigs | G3: Size Group | H3: Retail ($) | I3: Sec.Mkt New ($) | J3: Sec.Mkt Used ($) | K3: Predicted ($) | L3: Residual ($) | M3: % Error | N3: ROI New (%) | O3: Value Flag
A4: 10179 | B4: Star Wars | C4: Millennium Falcon | D4: 2007 | E4: 5195 | F4: 5 | G4: =IF(E4>=800,1,IF(E4>=300,2,IF(E4>=100,3,4))) -> 1 | H4: 499.99 | I4: 0 | J4: 0 | K4: ='🧮 Price Calculator'!$B$30+'🧮 Price Calculator'!$B$31*E4+'🧮 Price Calculator'!$B$32*F4+'🧮 Price Calculator'!$B$33*G4+'🧮 Price Calculator'!$B$34*IFERROR(MATCH(B4,'🎯 Theme Analysis'!$A$3:$A$50,0)-1,0) -> 397.8447 | L4: =H4-K4 -> 102.1453 | M4: =IF(H4<>0,ABS(L4)/H4,0) -> 0.20429469 | N4: =IF(H4<>0,(I4-H4)/H4*100,0) -> -100 | O4: =IF(M4>0.15,"UNDERPRICED",IF(M4>0.05,"FAIR VALUE","OVERPRICED")) -> UNDERPRICED
A5: 10188 | B5: Star Wars | C5: Death Star | D5: 2008 | E5: 3803 | F5: 22 | G5: =IF(E5>=800,1,IF(E5>=300,2,IF(E5>=100,3,4))) -> 1 | H5: 399.99 | I5: 490.38 | J5: 326.03 | K5: ='🧮 Price Calculator'!$B$30+'🧮 Price Calculator'!$B$31*E5+'🧮 Price Calculator'!$B$32*F5+'🧮 Price Calculator'!$B$33*G5+'🧮 Price Calculator'!$B$34*IFERROR(MATCH(B5,'🎯 Theme Analysis'!$A$3:$A$50,0)-1,0) -> 329.4669 | L5: =H5-K5 -> 70.5231 | M5: =IF(H5<>0,ABS(L5)/H5,0) -> 0.17631216 | N5: =IF(H5<>0,(I5-H5)/H5*100,0) -> 22.598065 | O5: =IF(M5>0.15,"UNDERPRICED",IF(M5>0.05,"FAIR VALUE","OVERPRICED")) -> UNDERPRICED
A6: 10221 | B6: Star Wars | C6: Super Star Destroyer | D6: 2011 | E6: 3152 | F6: 5 | G6: =IF(E6>=800,1,IF(E6>=300,2,IF(E6>=100,3,4))) -> 1 | H6: 399.99 | I6: 648.3 | J6: 511.73 | K6: ='🧮 Price Calculator'!$B$30+'🧮 Price Calculator'!$B$31*E6+'🧮 Price Calculator'!$B$32*F6+'🧮 Price Calculator'!$B$33*G6+'🧮 Price Calculator'!$B$34*IFERROR(MATCH(B6,'🎯 Theme Analysis'!$A$3:$A$50,0)-1,0) -> 255.8562 | L6: =H6-K6 -> 144.1338 | M6: =IF(H6<>0,ABS(L6)/H6,0) -> 0.36034351 | N6: =IF(H6<>0,(I6-H6)/H6*100,0) -> 62.079052 | O6: =IF(M6>0.15,"UNDERPRICED",IF(M6>0.05,"FAIR VALUE","OVERPRICED")) -> UNDERPRICED
A7: 10234 | B7: Advanced Models | C7: Sydney Opera House | D7: 2013 | E7: 2989 | F7: 0 | G7: =IF(E7>=800,1,IF(E7>=300,2,IF(E7>=100,3,4))) -> 1 | H7: 319.99 | I7: 323.52 | J7: 256.8 | K7: ='🧮 Price Calculator'!$B$30+'🧮 Price Calculator'!$B$31*E7+'🧮 Price Calculator'!$B$32*F7+'🧮 Price Calculator'!$B$33*G7+'🧮 Price Calculator'!$B$34*IFERROR(MATCH(B7,'🎯 Theme Analysis'!$A$3:$A$50,0)-1,0) -> 235.2535 | L7: =H7-K7 -> 84.7365 | M7: =IF(H7<>0,ABS(L7)/H7,0) -> 0.26480984 | N7: =IF(H7<>0,(I7-H7)/H7*100,0) -> 1.1031595 | O7: =IF(M7>0.15,"UNDERPRICED",IF(M7>0.05,"FAIR VALUE","OVERPRICED")) -> UNDERPRICED
A8: 75059 | B8: Star Wars | C8: Sandcrawler | D8: 2014 | E8: 3296 | F8: 7 | G8: =IF(E8>=800,1,IF(E8>=300,2,IF(E8>=100,3,4))) -> 1 | H8: 299.99 | I8: 303 | J8: 250 | K8: ='🧮 Price Calculator'!$B$30+'🧮 Price Calculator'!$B$31*E8+'🧮 Price Calculator'!$B$32*F8+'🧮 Price Calculator'!$B$33*G8+'🧮 Price Calculator'!$B$34*IFERROR(MATCH(B8,'🎯 Theme Analysis'!$A$3:$A$50,0)-1,0) -> 269.2014 | L8: =H8-K8 -> 30.7886 | M8: =IF(H8<>0,ABS(L8)/H8,0) -> 0.10263209 | N8: =IF(H8<>0,(I8-H8)/H8*100,0) -> 1.0033668 | O8: =IF(M8>0.15,"UNDERPRICED",IF(M8>0.05,"FAIR VALUE","OVERPRICED")) -> FAIR VALUE
A9: 10189 | B9: Advanced Models | C9: Taj Mahal | D9: 2008 | E9: 5922 | F9: 0 | G9: =IF(E9>=800,1,IF(E9>=300,2,IF(E9>=100,3,4))) -> 1 | H9: 299.99 | I9: 2394.19 | J9: 965.53 | K9: ='🧮 Price Calculator'!$B$30+'🧮 Price Calculator'!$B$31*E9+'🧮 Price Calculator'!$B$32*F9+'🧮 Price Calculator'!$B$33*G9+'🧮 Price Calculator'!$B$34*IFERROR(MATCH(B9,'🎯 Theme Analysis'!$A$3:$A$50,0)-1,0) -> 439.097 | L9: =H9-K9 -> -139.107 | M9: =IF(H9<>0,ABS(L9)/H9,0) -> 0.46370546 | N9: =IF(H9<>0,(I9-H9)/H9*100,0) -> 698.08994 | O9: =IF(M9>0.15,"UNDERPRICED",IF(M9>0.05,"FAIR VALUE","OVERPRICED")) -> UNDERPRICED
A10: 10030 | B10: Star Wars | C10: Imperial Star Destroyer | D10: 2002 | E10: 3096 | F10: 0 | G10: =IF(E10>=800,1,IF(E10>=300,2,IF(E10>=100,3,4))) -> 1 | H10: 298.99 | I10: 1527 | J10: 783.38 | K10: ='🧮 Price Calculator'!$B$30+'🧮 Price Calculator'!$B$31*E10+'🧮 Price Calculator'!$B$32*F10+'🧮 Price Calculator'!$B$33*G10+'🧮 Price Calculator'!$B$34*IFERROR(MATCH(B10,'🎯 Theme Analysis'!$A$3:$A$50,0)-1,0) -> 243.6212 | L10: =H10-K10 -> 55.3688 | M10: =IF(H10<>0,ABS(L10)/H10,0) -> 0.18518613 | N10: =IF(H10<>0,(I10-H10)/H10*100,0) -> 410.71942 | O10: =IF(M10>0.15,"UNDERPRICED",IF(M10>0.05,"FAIR VALUE","OVERPRICED")) -> UNDERPRICED
A11: 10212 | B11: Star Wars | C11: Imperial Shuttle | D11: 2010 | E11: 2503 | F11: 5 | G11: =IF(E11>=800,1,IF(E11>=300,2,IF(E11>=100,3,4))) -> 1 | H11: 259.99 | I11: 453.96 | J11: 333.53 | K11: ='🧮 Price Calculator'!$B$30+'🧮 Price Calculator'!$B$31*E11+'🧮 Price Calculator'!$B$32*F11+'🧮 Price Calculator'!$B$33*G11+'🧮 Price Calculator'!$B$34*IFERROR(MATCH(B11,'🎯 Theme Analysis'!$A$3:$A$50,0)-1,0) -> 210.7507 | L11: =H11-K11 -> 49.2393 | M11: =IF(H11<>0,ABS(L11)/H11,0) -> 0.18938921 | N11: =IF(H11<>0,(I11-H11)/H11*100,0) -> 74.606716 | O11: =IF(M11>0.15,"UNDERPRICED",IF(M11>0.05,"FAIR VALUE","OVERPRICED")) -> UNDERPRICED
A12: 10196 | B12: Advanced Models | C12: Grand Carousel | D12: 2009 | E12: 3263 | F12: 9 | G12: =IF(E12>=800,1,IF(E12>=300,2,IF(E12>=100,3,4))) -> 1 | H12: 249.99 | I12: 2278 | J12: 1215.07 | K12: ='🧮 Price Calculator'!$B$30+'🧮 Price Calculator'!$B$31*E12+'🧮 Price Calculator'!$B$32*F12+'🧮 Price Calculator'!$B$33*G12+'🧮 Price Calculator'!$B$34*IFERROR(MATCH(B12,'🎯 Theme Analysis'!$A$3:$A$50,0)-1,0) -> 269.3139 | L12: =H12-K12 -> -19.3239 | M12: =IF(H12<>0,ABS(L12)/H12,0) -> 0.077298692 | N12: =IF(H12<>0,(I12-H12)/H12*100,0) -> 811.23645 | O12: =IF(M12>0.15,"UNDERPRICED",IF(M12>0.05,"FAIR VALUE","OVERPRICED")) -> FAIR VALUE
